Workbook

Sheet Model
B2: ArduVCU Digital Twin — lead-acid discharge & pacing model
B3: Greenpower F24 · 24 V (2 × 12 V SLA in series) · built Oct 2026, replaces an earlier static illustration with a real, auditable model
B7: What this model does
B8: Predicts pack terminal voltage over a race from Peukert's law and internal-resistance sag, and checks the 0.05 V/min pacing budget that the ArduVCU firmware enforces (Limp Mode at 21.0 V). Edit any input in blue — every output and the whole Discharge sheet recompute live.
B11: Battery & race parameters (editable) | J11: Race prediction
B12: Capacity at 20h rate, C (Ah) | D12: 20 | J12: Peukert runtime t_run (min) | L12: =Model!D14*(Model!D12/(Model!D15*Model!D14))^Model!D13*60 -> 95.896412
B13: Peukert exponent, k | D13: 1.15 | J13: Terminal voltage at start (V) | L13: =Model!D17-Model!D15*Model!D16 -> 24.32
B14: Rating period, H (h) | D14: 20 | J14: Time to Limp Mode (min) | L14: =IF((Model!D19-Model!D18+Model!D15*Model!D16)<=0,"never",Model!L12*(1-(Model!D19-Model!D18+Model!D15*Model!D16)/(Model!D17-Model!D18))) -> 93.640026
B15: Average current draw, I (A) | D15: 9 | J15: Average discharge gradient (V/min) | L15: =IF(Model!L14="never",(Model!L13-(Model!D18-Model!D15*Model!D16))/Model!L12,(Model!L13-Model!D19)/Model!L14) -> 0.035454924
B16: Pack internal resistance, R (ohm) | D16: 0.12 | J16: Verdict | L16: =IF(AND(Model!L14<>"never",Model!L14<Model!D21),"LIMP at "&TEXT(Model!L14,"0.0")&" min — reduce current to "&TEXT(Model!D12/(Model!D14*POWER(Model!D21/60/Model!D14,1/Model!D13)),"0.0")&" A",IF(Model!L12<Model!D21,"FLAT — pack empties at "&TEXT(Model!L12,"0.0")&" min, before the "&TEXT(Model!D21,"0")&"-min finish","FINISHES — on pace")) -> FINISHES — on pace
B17: Open-circuit voltage, full (V) | D17: 25.4
B18: Open-circuit voltage, empty (V) | D18: 22
B19: Limp threshold (V) | D19: 21 | J19: Model sanity checks (live)
B20: Pacing budget (V/min) | D20: 0.05 | J20: Check | K20: Actual | L20: Expected | M20: Tolerance | N20: Status | O20: Detail
B21: Race duration (min) | D21: 90 | J21: Peukert self-check: runtime at C/H equals H | K21: =Model!D14*(Model!D12/((Model!D12/Model!D14)*Model!D14))^Model!D13*60 -> 1200 | L21: =Model!D14*60 -> 1200 | M21: 0.01 | N21: =IF(ABS(Model!K21-Model!L21)<=Model!M21,"PASS","FAIL") -> PASS
J22: t_limp <= t_run (Limp before empty) | K22: =IF(Model!L14="never",0,MAX(0,Model!L14-Model!L12)) -> 0 | L22: 0 | M22: 0.001 | N22: =IF(ABS(Model!K22-Model!L22)<=Model!M22,"PASS","FAIL") -> PASS
J23: V at t=90 min matches Model sheet | K23: =Discharge!G98 -> 21.129057 | L23: =Model!D18+(Model!D17-Model!D18)*MAX(0,1-90/Model!L12)-Model!D15*Model!D16 -> 21.129057 | M23: 0.001 | N23: =IF(ABS(Model!K23-Model!L23)<=Model!M23,"PASS","FAIL") -> PASS
J26: Model assumptions (first-order, deliberate): linear open-circuit voltage vs SOC; constant internal resistance; constant average current; no temperature, ageing or surface-charge effects. If I·R < 1 V, the terminal voltage never reaches 21 V: t_limp reports 'never' and the binding limit becomes Peukert runtime (verdict: FLAT if the pack empties before the finish). Every simplification is disclosed — the model is a pacing tool, not a cell datasheet. Interactive browser version: prestonforge.github.io/digital-twin.html. Part of github.com/prestonforge/ArduVCU.

Sheet Discharge
B2: Discharge curve — t = 0…120 min, 1-minute steps
B3: Chart source: plot Terminal V and Budget line vs t. Limp Mode engages when Terminal V <= 21.0 V.
B7: t (min) | C7: I (A) | D7: Ah drawn | E7: SOC | F7: OCV (V) | G7: Terminal V | H7: dV/dt (V/min) | I7: Budget line (V) | J7: State
B8: 0 | C8: =Model!D15 -> 9 | D8: =Discharge!C8*Discharge!B8/60 -> 0 | E8: =MAX(0,1-Discharge!B8/Model!L12) -> 1 | F8: =Model!D18+(Model!D17-Model!D18)*Discharge!E8 -> 25.4 | G8: =Discharge!F8-Discharge!C8*Model!D16 -> 24.32 | H8: 0 | I8: =Model!L13-Model!D20*Discharge!B8 -> 24.32 | J8: =IF(Discharge!B8>Model!L12,"EMPTY",IF(Discharge!G8<=Model!D19,"LIMP","NOMINAL")) -> NOMINAL
B9: 1 | C9: =Model!D15 -> 9 | D9: =Discharge!C9*Discharge!B9/60 -> 0.15 | E9: =MAX(0,1-Discharge!B9/Model!L12) -> 0.98957208 | F9: =Model!D18+(Model!D17-Model!D18)*Discharge!E9 -> 25.364545 | G9: =Discharge!F9-Discharge!C9*Model!D16 -> 24.284545 | H9: =Discharge!G9-Discharge!G8 -> -0.035454924 | I9: =Model!L13-Model!D20*Discharge!B9 -> 24.27 | J9: =IF(Discharge!B9>Model!L12,"EMPTY",IF(Discharge!G9<=Model!D19,"LIMP","NOMINAL")) -> NOMINAL
B10: 2 | C10: =Model!D15 -> 9 | D10: =Discharge!C10*Discharge!B10/60 -> 0.3 | E10: =MAX(0,1-Discharge!B10/Model!L12) -> 0.97914416 | F10: =Model!D18+(Model!D17-Model!D18)*Discharge!E10 -> 25.32909 | G10: =Discharge!F10-Discharge!C10*Model!D16 -> 24.24909 | H10: =Discharge!G10-Discharge!G9 -> -0.035454924 | I10: =Model!L13-Model!D20*Discharge!B10 -> 24.22 | J10: =IF(Discharge!B10>Model!L12,"EMPTY",IF(Discharge!G10<=Model!D19,"LIMP","NOMINAL")) -> NOMINAL
B11: 3 | C11: =Model!D15 -> 9 | D11: =Discharge!C11*Discharge!B11/60 -> 0.45 | E11: =MAX(0,1-Discharge!B11/Model!L12) -> 0.96871624 | F11: =Model!D18+(Model!D17-Model!D18)*Discharge!E11 -> 25.293635 | G11: =Discharge!F11-Discharge!C11*Model!D16 -> 24.213635 | H11: =Discharge!G11-Discharge!G10 -> -0.035454924 | I11: =Model!L13-Model!D20*Discharge!B11 -> 24.17 | J11: =IF(Discharge!B11>Model!L12,"EMPTY",IF(Discharge!G11<=Model!D19,"LIMP","NOMINAL")) -> NOMINAL
B12: 4 | C12: =Model!D15 -> 9 | D12: =Discharge!C12*Discharge!B12/60 -> 0.6 | E12: =MAX(0,1-Discharge!B12/Model!L12) -> 0.95828832 | F12: =Model!D18+(Model!D17-Model!D18)*Discharge!E12 -> 25.25818 | G12: =Discharge!F12-Discharge!C12*Model!D16 -> 24.17818 | H12: =Discharge!G12-Discharge!G11 -> -0.035454924 | I12: =Model!L13-Model!D20*Discharge!B12 -> 24.12 | J12: =IF(Discharge!B12>Model!L12,"EMPTY",IF(Discharge!G12<=Model!D19,"LIMP","NOMINAL")) -> NOMINAL
B13: 5 | C13: =Model!D15 -> 9 | D13: =Discharge!C13*Discharge!B13/60 -> 0.75 | E13: =MAX(0,1-Discharge!B13/Model!L12) -> 0.94786041 | F13: =Model!D18+(Model!D17-Model!D18)*Discharge!E13 -> 25.222725 | G13: =Discharge!F13-Discharge!C13*Model!D16 -> 24.142725 | H13: =Discharge!G13-Discharge!G12 -> -0.035454924 | I13: =Model!L13-Model!D20*Discharge!B13 -> 24.07 | J13: =IF(Discharge!B13>Model!L12,"EMPTY",IF(Discharge!G13<=Model!D19,"LIMP","NOMINAL")) -> NOMINAL
B14: 6 | C14: =Model!D15 -> 9 | D14: =Discharge!C14*Discharge!B14/60 -> 0.9 | E14: =MAX(0,1-Discharge!B14/Model!L12) -> 0.93743249 | F14: =Model!D18+(Model!D17-Model!D18)*Discharge!E14 -> 25.18727 | G14: =Discharge!F14-Discharge!C14*Model!D16 -> 24.10727 | H14: =Discharge!G14-Discharge!G13 -> -0.035454924 | I14: =Model!L13-Model!D20*Discharge!B14 -> 24.02 | J14: =IF(Discharge!B14>Model!L12,"EMPTY",IF(Discharge!G14<=Model!D19,"LIMP","NOMINAL")) -> NOMINAL
B15: 7 | C15: =Model!D15 -> 9 | D15: =Discharge!C15*Discharge!B15/60 -> 1.05 | E15: =MAX(0,1-Discharge!B15/Model!L12) -> 0.92700457 | F15: =Model!D18+(Model!D17-Model!D18)*Discharge!E15 -> 25.151816 | G15: =Discharge!F15-Discharge!C15*Model!D16 -> 24.071816 | H15: =Discharge!G15-Discharge!G14 -> -0.035454924 | I15: =Model!L13-Model!D20*Discharge!B15 -> 23.97 | J15: =IF(Discharge!B15>Model!L12,"EMPTY",IF(Discharge!G15<=Model!D19,"LIMP","NOMINAL")) -> NOMINAL
B16: 8 | C16: =Model!D15 -> 9 | D16: =Discharge!C16*Discharge!B16/60 -> 1.2 | E16: =MAX(0,1-Discharge!B16/Model!L12) -> 0.91657665 | F16: =Model!D18+(Model!D17-Model!D18)*Discharge!E16 -> 25.116361 | G16: =Discharge!F16-Discharge!C16*Model!D16 -> 24.036361 | H16: =Discharge!G16-Discharge!G15 -> -0.035454924 | I16: =Model!L13-Model!D20*Discharge!B16 -> 23.92 | J16: =IF(Discharge!B16>Model!L12,"EMPTY",IF(Discharge!G16<=Model!D19,"LIMP","NOMINAL")) -> NOMINAL
B17: 9 | C17: =Model!D15 -> 9 | D17: =Discharge!C17*Discharge!B17/60 -> 1.35 | E17: =MAX(0,1-Discharge!B17/Model!L12) -> 0.90614873 | F17: =Model!D18+(Model!D17-Model!D18)*Discharge!E17 -> 25.080906 | G17: =Discharge!F17-Discharge!C17*Model!D16 -> 24.000906 | H17: =Discharge!G17-Discharge!G16 -> -0.035454924 | I17: =Model!L13-Model!D20*Discharge!B17 -> 23.87 | J17: =IF(Discharge!B17>Model!L12,"EMPTY",IF(Discharge!G17<=Model!D19,"LIMP","NOMINAL")) -> NOMINAL
B18: 10 | C18: =Model!D15 -> 9 | D18: =Discharge!C18*Discharge!B18/60 -> 1.5 | E18: =MAX(0,1-Discharge!B18/Model!L12) -> 0.89572081 | F18: =Model!D18+(Model!D17-Model!D18)*Discharge!E18 -> 25.045451 | G18: =Discharge!F18-Discharge!C18*Model!D16 -> 23.965451 | H18: =Discharge!G18-Discharge!G17 -> -0.035454924 | I18: =Model!L13-Model!D20*Discharge!B18 -> 23.82 | J18: =IF(Discharge!B18>Model!L12,"EMPTY",IF(Discharge!G18<=Model!D19,"LIMP","NOMINAL")) -> NOMINAL
B19: 11 | C19: =Model!D15 -> 9 | D19: =Discharge!C19*Discharge!B19/60 -> 1.65 | E19: =MAX(0,1-Discharge!B19/Model!L12) -> 0.88529289 | F19: =Model!D18+(Model!D17-Model!D18)*Discharge!E19 -> 25.009996 | G19: =Discharge!F19-Discharge!C19*Model!D16 -> 23.929996 | H19: =Discharge!G19-Discharge!G18 -> -0.035454924 | I19: =Model!L13-Model!D20*Discharge!B19 -> 23.77 | J19: =IF(Discharge!B19>Model!L12,"EMPTY",IF(Discharge!G19<=Model!D19,"LIMP","NOMINAL")) -> NOMINAL
B20: 12 | C20: =Model!D15 -> 9 | D20: =Discharge!C20*Discharge!B20/60 -> 1.8 | E20: =MAX(0,1-Discharge!B20/Model!L12) -> 0.87486497 | F20: =Model!D18+(Model!D17-Model!D18)*Discharge!E20 -> 24.974541 | G20: =Discharge!F20-Discharge!C20*Model!D16 -> 23.894541 | H20: =Discharge!G20-Discharge!G19 -> -0.035454924 | I20: =Model!L13-Model!D20*Discharge!B20 -> 23.72 | J20: =IF(Discharge!B20>Model!L12,"EMPTY",IF(Discharge!G20<=Model!D19,"LIMP","NOMINAL")) -> NOMINAL
B21: 13 | C21: =Model!D15 -> 9 | D21: =Discharge!C21*Discharge!B21/60 -> 1.95 | E21: =MAX(0,1-Discharge!B21/Model!L12) -> 0.86443706 | F21: =Model!D18+(Model!D17-Model!D18)*Discharge!E21 -> 24.939086 | G21: =Discharge!F21-Discharge!C21*Model!D16 -> 23.859086 | H21: =Discharge!G21-Discharge!G20 -> -0.035454924 | I21: =Model!L13-Model!D20*Discharge!B21 -> 23.67 | J21: =IF(Discharge!B21>Model!L12,"EMPTY",IF(Discharge!G21<=Model!D19,"LIMP","NOMINAL")) -> NOMINAL
B22: 14 | C22: =Model!D15 -> 9 | D22: =Discharge!C22*Discharge!B22/60 -> 2.1 | E22: =MAX(0,1-Discharge!B22/Model!L12) -> 0.85400914 | F22: =Model!D18+(Model!D17-Model!D18)*Discharge!E22 -> 24.903631 | G22: =Discharge!F22-Discharge!C22*Model!D16 -> 23.823631 | H22: =Discharge!G22-Discharge!G21 -> -0.035454924 | I22: =Model!L13-Model!D20*Discharge!B22 -> 23.62 | J22: =IF(Discharge!B22>Model!L12,"EMPTY",IF(Discharge!G22<=Model!D19,"LIMP","NOMINAL")) -> NOMINAL
B23: 15 | C23: =Model!D15 -> 9 | D23: =Discharge!C23*Discharge!B23/60 -> 2.25 | E23: =MAX(0,1-Discharge!B23/Model!L12) -> 0.84358122 | F23: =Model!D18+(Model!D17-Model!D18)*Discharge!E23 -> 24.868176 | G23: =Discharge!F23-Discharge!C23*Model!D16 -> 23.788176 | H23: =Discharge!G23-Discharge!G22 -> -0.035454924 | I23: =Model!L13-Model!D20*Discharge!B23 -> 23.57 | J23: =IF(Discharge!B23>Model!L12,"EMPTY",IF(Discharge!G23<=Model!D19,"LIMP","NOMINAL")) -> NOMINAL
B24: 16 | C24: =Model!D15 -> 9 | D24: =Discharge!C24*Discharge!B24/60 -> 2.4 | E24: =MAX(0,1-Discharge!B24/Model!L12) -> 0.8331533 | F24: =Model!D18+(Model!D17-Model!D18)*Discharge!E24 -> 24.832721 | G24: =Discharge!F24-Discharge!C24*Model!D16 -> 23.752721 | H24: =Discharge!G24-Discharge!G23 -> -0.035454924 | I24: =Model!L13-Model!D20*Discharge!B24 -> 23.52 | J24: =IF(Discharge!B24>Model!L12,"EMPTY",IF(Discharge!G24<=Model!D19,"LIMP","NOMINAL")) -> NOMINAL
B25: 17 | C25: =Model!D15 -> 9 | D25: =Discharge!C25*Discharge!B25/60 -> 2.55 | E25: =MAX(0,1-Discharge!B25/Model!L12) -> 0.82272538 | F25: =Model!D18+(Model!D17-Model!D18)*Discharge!E25 -> 24.797266 | G25: =Discharge!F25-Discharge!C25*Model!D16 -> 23.717266 | H25: =Discharge!G25-Discharge!G24 -> -0.035454924 | I25: =Model!L13-Model!D20*Discharge!B25 -> 23.47 | J25: =IF(Discharge!B25>Model!L12,"EMPTY",IF(Discharge!G25<=Model!D19,"LIMP","NOMINAL")) -> NOMINAL
B26: 18 | C26: =Model!D15 -> 9 | D26: =Discharge!C26*Discharge!B26/60 -> 2.7 | E26: =MAX(0,1-Discharge!B26/Model!L12) -> 0.81229746 | F26: =Model!D18+(Model!D17-Model!D18)*Discharge!E26 -> 24.761811 | G26: =Discharge!F26-Discharge!C26*Model!D16 -> 23.681811 | H26: =Discharge!G26-Discharge!G25 -> -0.035454924 | I26: =Model!L13-Model!D20*Discharge!B26 -> 23.42 | J26: =IF(Discharge!B26>Model!L12,"EMPTY",IF(Discharge!G26<=Model!D19,"LIMP","NOMINAL")) -> NOMINAL
B27: 19 | C27: =Model!D15 -> 9 | D27: =Discharge!C27*Discharge!B27/60 -> 2.85 | E27: =MAX(0,1-Discharge!B27/Model!L12) -> 0.80186954 | F27: =Model!D18+(Model!D17-Model!D18)*Discharge!E27 -> 24.726356 | G27: =Discharge!F27-Discharge!C27*Model!D16 -> 23.646356 | H27: =Discharge!G27-Discharge!G26 -> -0.035454924 | I27: =Model!L13-Model!D20*Discharge!B27 -> 23.37 | J27: =IF(Discharge!B27>Model!L12,"EMPTY",IF(Discharge!G27<=Model!D19,"LIMP","NOMINAL")) -> NOMINAL
B28: 20 | C28: =Model!D15 -> 9 | D28: =Discharge!C28*Discharge!B28/60 -> 3 | E28: =MAX(0,1-Discharge!B28/Model!L12) -> 0.79144162 | F28: =Model!D18+(Model!D17-Model!D18)*Discharge!E28 -> 24.690902 | G28: =Discharge!F28-Discharge!C28*Model!D16 -> 23.610902 | H28: =Discharge!G28-Discharge!G27 -> -0.035454924 | I28: =Model!L13-Model!D20*Discharge!B28 -> 23.32 | J28: =IF(Discharge!B28>Model!L12,"EMPTY",IF(Discharge!G28<=Model!D19,"LIMP","NOMINAL")) -> NOMINAL
B29: 21 | C29: =Model!D15 -> 9 | D29: =Discharge!C29*Discharge!B29/60 -> 3.15 | E29: =MAX(0,1-Discharge!B29/Model!L12) -> 0.78101371 | F29: =Model!D18+(Model!D17-Model!D18)*Discharge!E29 -> 24.655447 | G29: =Discharge!F29-Discharge!C29*Model!D16 -> 23.575447 | H29: =Discharge!G29-Discharge!G28 -> -0.035454924 | I29: =Model!L13-Model!D20*Discharge!B29 -> 23.27 | J29: =IF(Discharge!B29>Model!L12,"EMPTY",IF(Discharge!G29<=Model!D19,"LIMP","NOMINAL")) -> NOMINAL
B30: 22 | C30: =Model!D15 -> 9 | D30: =Discharge!C30*Discharge!B30/60 -> 3.3 | E30: =MAX(0,1-Discharge!B30/Model!L12) -> 0.77058579 | F30: =Model!D18+(Model!D17-Model!D18)*Discharge!E30 -> 24.619992 | G30: =Discharge!F30-Discharge!C30*Model!D16 -> 23.539992 | H30: =Discharge!G30-Discharge!G29 -> -0.035454924 | I30: =Model!L13-Model!D20*Discharge!B30 -> 23.22 | J30: =IF(Discharge!B30>Model!L12,"EMPTY",IF(Discharge!G30<=Model!D19,"LIMP","NOMINAL")) -> NOMINAL
B31: 23 | C31: =Model!D15 -> 9 | D31: =Discharge!C31*Discharge!B31/60 -> 3.45 | E31: =MAX(0,1-Discharge!B31/Model!L12) -> 0.76015787 | F31: =Model!D18+(Model!D17-Model!D18)*Discharge!E31 -> 24.584537 | G31: =Discharge!F31-Discharge!C31*Model!D16 -> 23.504537 | H31: =Discharge!G31-Discharge!G30 -> -0.035454924 | I31: =Model!L13-Model!D20*Discharge!B31 -> 23.17 | J31: =IF(Discharge!B31>Model!L12,"EMPTY",IF(Discharge!G31<=Model!D19,"LIMP","NOMINAL")) -> NOMINAL
B32: 24 | C32: =Model!D15 -> 9 | D32: =Discharge!C32*Discharge!B32/60 -> 3.6 | E32: =MAX(0,1-Discharge!B32/Model!L12) -> 0.74972995 | F32: =Model!D18+(Model!D17-Model!D18)*Discharge!E32 -> 24.549082 | G32: =Discharge!F32-Discharge!C32*Model!D16 -> 23.469082 | H32: =Discharge!G32-Discharge!G31 -> -0.035454924 | I32: =Model!L13-Model!D20*Discharge!B32 -> 23.12 | J32: =IF(Discharge!B32>Model!L12,"EMPTY",IF(Discharge!G32<=Model!D19,"LIMP","NOMINAL")) -> NOMINAL
B33: 25 | C33: =Model!D15 -> 9 | D33: =Discharge!C33*Discharge!B33/60 -> 3.75 | E33: =MAX(0,1-Discharge!B33/Model!L12) -> 0.73930203 | F33: =Model!D18+(Model!D17-Model!D18)*Discharge!E33 -> 24.513627 | G33: =Discharge!F33-Discharge!C33*Model!D16 -> 23.433627 | H33: =Discharge!G33-Discharge!G32 -> -0.035454924 | I33: =Model!L13-Model!D20*Discharge!B33 -> 23.07 | J33: =IF(Discharge!B33>Model!L12,"EMPTY",IF(Discharge!G33<=Model!D19,"LIMP","NOMINAL")) -> NOMINAL
B34: 26 | C34: =Model!D15 -> 9 | D34: =Discharge!C34*Discharge!B34/60 -> 3.9 | E34: =MAX(0,1-Discharge!B34/Model!L12) -> 0.72887411 | F34: =Model!D18+(Model!D17-Model!D18)*Discharge!E34 -> 24.478172 | G34: =Discharge!F34-Discharge!C34*Model!D16 -> 23.398172 | H34: =Discharge!G34-Discharge!G33 -> -0.035454924 | I34: =Model!L13-Model!D20*Discharge!B34 -> 23.02 | J34: =IF(Discharge!B34>Model!L12,"EMPTY",IF(Discharge!G34<=Model!D19,"LIMP","NOMINAL")) -> NOMINAL
B35: 27 | C35: =Model!D15 -> 9 | D35: =Discharge!C35*Discharge!B35/60 -> 4.05 | E35: =MAX(0,1-Discharge!B35/Model!L12) -> 0.71844619 | F35: =Model!D18+(Model!D17-Model!D18)*Discharge!E35 -> 24.442717 | G35: =Discharge!F35-Discharge!C35*Model!D16 -> 23.362717 | H35: =Discharge!G35-Discharge!G34 -> -0.035454924 | I35: =Model!L13-Model!D20*Discharge!B35 -> 22.97 | J35: =IF(Discharge!B35>Model!L12,"EMPTY",IF(Discharge!G35<=Model!D19,"LIMP","NOMINAL")) -> NOMINAL
B36: 28 | C36: =Model!D15 -> 9 | D36: =Discharge!C36*Discharge!B36/60 -> 4.2 | E36: =MAX(0,1-Discharge!B36/Model!L12) -> 0.70801827 | F36: =Model!D18+(Model!D17-Model!D18)*Discharge!E36 -> 24.407262 | G36: =Discharge!F36-Discharge!C36*Model!D16 -> 23.327262 | H36: =Discharge!G36-Discharge!G35 -> -0.035454924 | I36: =Model!L13-Model!D20*Discharge!B36 -> 22.92 | J36: =IF(Discharge!B36>Model!L12,"EMPTY",IF(Discharge!G36<=Model!D19,"LIMP","NOMINAL")) -> NOMINAL
B37: 29 | C37: =Model!D15 -> 9 | D37: =Discharge!C37*Discharge!B37/60 -> 4.35 | E37: =MAX(0,1-Discharge!B37/Model!L12) -> 0.69759036 | F37: =Model!D18+(Model!D17-Model!D18)*Discharge!E37 -> 24.371807 | G37: =Discharge!F37-Discharge!C37*Model!D16 -> 23.291807 | H37: =Discharge!G37-Discharge!G36 -> -0.035454924 | I37: =Model!L13-Model!D20*Discharge!B37 -> 22.87 | J37: =IF(Discharge!B37>Model!L12,"EMPTY",IF(Discharge!G37<=Model!D19,"LIMP","NOMINAL")) -> NOMINAL
B38: 30 | C38: =Model!D15 -> 9 | D38: =Discharge!C38*Discharge!B38/60 -> 4.5 | E38: =MAX(0,1-Discharge!B38/Model!L12) -> 0.68716244 | F38: =Model!D18+(Model!D17-Model!D18)*Discharge!E38 -> 24.336352 | G38: =Discharge!F38-Discharge!C38*Model!D16 -> 23.256352 | H38: =Discharge!G38-Discharge!G37 -> -0.035454924 | I38: =Model!L13-Model!D20*Discharge!B38 -> 22.82 | J38: =IF(Discharge!B38>Model!L12,"EMPTY",IF(Discharge!G38<=Model!D19,"LIMP","NOMINAL")) -> NOMINAL
B39: 31 | C39: =Model!D15 -> 9 | D39: =Discharge!C39*Discharge!B39/60 -> 4.65 | E39: =MAX(0,1-Discharge!B39/Model!L12) -> 0.67673452 | F39: =Model!D18+(Model!D17-Model!D18)*Discharge!E39 -> 24.300897 | G39: =Discharge!F39-Discharge!C39*Model!D16 -> 23.220897 | H39: =Discharge!G39-Discharge!G38 -> -0.035454924 | I39: =Model!L13-Model!D20*Discharge!B39 -> 22.77 | J39: =IF(Discharge!B39>Model!L12,"EMPTY",IF(Discharge!G39<=Model!D19,"LIMP","NOMINAL")) -> NOMINAL
B40: 32 | C40: =Model!D15 -> 9 | D40: =Discharge!C40*Discharge!B40/60 -> 4.8 | E40: =MAX(0,1-Discharge!B40/Model!L12) -> 0.6663066 | F40: =Model!D18+(Model!D17-Model!D18)*Discharge!E40 -> 24.265442 | G40: =Discharge!F40-Discharge!C40*Model!D16 -> 23.185442 | H40: =Discharge!G40-Discharge!G39 -> -0.035454924 | I40: =Model!L13-Model!D20*Discharge!B40 -> 22.72 | J40: =IF(Discharge!B40>Model!L12,"EMPTY",IF(Discharge!G40<=Model!D19,"LIMP","NOMINAL")) -> NOMINAL
B41: 33 | C41: =Model!D15 -> 9 | D41: =Discharge!C41*Discharge!B41/60 -> 4.95 | E41: =MAX(0,1-Discharge!B41/Model!L12) -> 0.65587868 | F41: =Model!D18+(Model!D17-Model!D18)*Discharge!E41 -> 24.229988 | G41: =Discharge!F41-Discharge!C41*Model!D16 -> 23.149988 | H41: =Discharge!G41-Discharge!G40 -> -0.035454924 | I41: =Model!L13-Model!D20*Discharge!B41 -> 22.67 | J41: =IF(Discharge!B41>Model!L12,"EMPTY",IF(Discharge!G41<=Model!D19,"LIMP","NOMINAL")) -> NOMINAL
B42: 34 | C42: =Model!D15 -> 9 | D42: =Discharge!C42*Discharge!B42/60 -> 5.1 | E42: =MAX(0,1-Discharge!B42/Model!L12) -> 0.64545076 | F42: =Model!D18+(Model!D17-Model!D18)*Discharge!E42 -> 24.194533 | G42: =Discharge!F42-Discharge!C42*Model!D16 -> 23.114533 | H42: =Discharge!G42-Discharge!G41 -> -0.035454924 | I42: =Model!L13-Model!D20*Discharge!B42 -> 22.62 | J42: =IF(Discharge!B42>Model!L12,"EMPTY",IF(Discharge!G42<=Model!D19,"LIMP","NOMINAL")) -> NOMINAL
B43: 35 | C43: =Model!D15 -> 9 | D43: =Discharge!C43*Discharge!B43/60 -> 5.25 | E43: =MAX(0,1-Discharge!B43/Model!L12) -> 0.63502284 | F43: =Model!D18+(Model!D17-Model!D18)*Discharge!E43 -> 24.159078 | G43: =Discharge!F43-Discharge!C43*Model!D16 -> 23.079078 | H43: =Discharge!G43-Discharge!G42 -> -0.035454924 | I43: =Model!L13-Model!D20*Discharge!B43 -> 22.57 | J43: =IF(Discharge!B43>Model!L12,"EMPTY",IF(Discharge!G43<=Model!D19,"LIMP","NOMINAL")) -> NOMINAL
B44: 36 | C44: =Model!D15 -> 9 | D44: =Discharge!C44*Discharge!B44/60 -> 5.4 | E44: =MAX(0,1-Discharge!B44/Model!L12) -> 0.62459492 | F44: =Model!D18+(Model!D17-Model!D18)*Discharge!E44 -> 24.123623 | G44: =Discharge!F44-Discharge!C44*Model!D16 -> 23.043623 | H44: =Discharge!G44-Discharge!G43 -> -0.035454924 | I44: =Model!L13-Model!D20*Discharge!B44 -> 22.52 | J44: =IF(Discharge!B44>Model!L12,"EMPTY",IF(Discharge!G44<=Model!D19,"LIMP","NOMINAL")) -> NOMINAL
...
